Traceback (most recent call last):
  File "C:\Users\ashej\.virtualenvs\jupyter-books-WZpnkDri\Lib\site-packages\jupyter_cache\executors\utils.py", line 51, in single_nb_execution
    executenb(
  File "C:\Users\ashej\.virtualenvs\jupyter-books-WZpnkDri\Lib\site-packages\nbclient\client.py", line 1204, in execute
    return NotebookClient(nb=nb, resources=resources, km=km, **kwargs).execute()
           ^^^^^^^^^^^^^^^^^^^^^^^^^^^^^^^^^^^^^^^^^^^^^^^^^^^^^^^^^^^^^^^^^^^^^
  File "C:\Users\ashej\.virtualenvs\jupyter-books-WZpnkDri\Lib\site-packages\nbclient\util.py", line 84, in wrapped
    return just_run(coro(*args, **kwargs))
           ^^^^^^^^^^^^^^^^^^^^^^^^^^^^^^^
  File "C:\Users\ashej\.virtualenvs\jupyter-books-WZpnkDri\Lib\site-packages\nbclient\util.py", line 62, in just_run
    return loop.run_until_complete(coro)
           ^^^^^^^^^^^^^^^^^^^^^^^^^^^^^
  File "C:\Users\ashej\AppData\Local\Programs\Python\Python311\Lib\asyncio\base_events.py", line 653, in run_until_complete
    return future.result()
           ^^^^^^^^^^^^^^^
  File "C:\Users\ashej\AppData\Local\Programs\Python\Python311\Lib\contextlib.py", line 222, in __aexit__
    await self.gen.athrow(typ, value, traceback)
  File "C:\Users\ashej\.virtualenvs\jupyter-books-WZpnkDri\Lib\site-packages\nbclient\client.py", line 608, in async_setup_kernel
    yield
  File "C:\Users\ashej\.virtualenvs\jupyter-books-WZpnkDri\Lib\site-packages\nbclient\client.py", line 663, in async_execute
    await self.async_execute_cell(
  File "C:\Users\ashej\.virtualenvs\jupyter-books-WZpnkDri\Lib\site-packages\nbclient\client.py", line 965, in async_execute_cell
    await self._check_raise_for_error(cell, cell_index, exec_reply)
  File "C:\Users\ashej\.virtualenvs\jupyter-books-WZpnkDri\Lib\site-packages\nbclient\client.py", line 862, in _check_raise_for_error
    raise CellExecutionError.from_cell_and_msg(cell, exec_reply_content)
nbclient.exceptions.CellExecutionError: An error occurred while executing the following cell:
------------------
from myst_nb import glue


import pandas as pd
from ipywidgets import interact, interactive, fixed, interact_manual, Layout, Box, VBox, HBox, Button, Output, Tab
# import ipywidgets as widgets
from IPython.display import display, display_html
import numpy as np
import math
import matplotlib.pyplot as plt
import seaborn as sns
from scipy.stats import norm
import markdown
from IPython.core.display import display, HTML
------------------

[1;31m---------------------------------------------------------------------------[0m
[1;31mModuleNotFoundError[0m                       Traceback (most recent call last)
Cell [1;32mIn[1], line 10[0m
[0;32m      8[0m [38;5;28;01mimport[39;00m [38;5;21;01mnumpy[39;00m [38;5;28;01mas[39;00m [38;5;21;01mnp[39;00m
[0;32m      9[0m [38;5;28;01mimport[39;00m [38;5;21;01mmath[39;00m
[1;32m---> 10[0m [38;5;28;01mimport[39;00m [38;5;21;01mmatplotlib[39;00m[38;5;21;01m.[39;00m[38;5;21;01mpyplot[39;00m [38;5;28;01mas[39;00m [38;5;21;01mplt[39;00m
[0;32m     11[0m [38;5;28;01mimport[39;00m [38;5;21;01mseaborn[39;00m [38;5;28;01mas[39;00m [38;5;21;01msns[39;00m
[0;32m     12[0m [38;5;28;01mfrom[39;00m [38;5;21;01mscipy[39;00m[38;5;21;01m.[39;00m[38;5;21;01mstats[39;00m [38;5;28;01mimport[39;00m norm

[1;31mModuleNotFoundError[0m: No module named 'matplotlib'
ModuleNotFoundError: No module named 'matplotlib'

