Traceback (most recent call last):
  File "C:\Users\Jim\anaconda3\envs\jupyter-book\lib\site-packages\jupyter_cache\executors\utils.py", line 56, in single_nb_execution
    record_timing=False,
  File "C:\Users\Jim\anaconda3\envs\jupyter-book\lib\site-packages\nbclient\client.py", line 1204, in execute
    return NotebookClient(nb=nb, resources=resources, km=km, **kwargs).execute()
  File "C:\Users\Jim\anaconda3\envs\jupyter-book\lib\site-packages\nbclient\util.py", line 84, in wrapped
    return just_run(coro(*args, **kwargs))
  File "C:\Users\Jim\anaconda3\envs\jupyter-book\lib\site-packages\nbclient\util.py", line 62, in just_run
    return loop.run_until_complete(coro)
  File "C:\Users\Jim\anaconda3\envs\jupyter-book\lib\asyncio\base_events.py", line 587, in run_until_complete
    return future.result()
  File "C:\Users\Jim\anaconda3\envs\jupyter-book\lib\site-packages\nbclient\client.py", line 664, in async_execute
    cell, index, execution_count=self.code_cells_executed + 1
  File "C:\Users\Jim\anaconda3\envs\jupyter-book\lib\site-packages\nbclient\client.py", line 965, in async_execute_cell
    await self._check_raise_for_error(cell, cell_index, exec_reply)
  File "C:\Users\Jim\anaconda3\envs\jupyter-book\lib\site-packages\nbclient\client.py", line 862, in _check_raise_for_error
    raise CellExecutionError.from_cell_and_msg(cell, exec_reply_content)
nbclient.exceptions.CellExecutionError: An error occurred while executing the following cell:
------------------
#required import
import pandas as pd
import numpy as np
import matplotlib.pyplot as plt
import seaborn as sns

##Machine Learning for Hackers, Drew Conway & John Myles-While, O'Reilly Media.
url = "https://raw.githubusercontent.com/johnmyleswhite/ML_for_Hackers/master/02-Exploration/data/01_heights_weights_genders.csv"
df = pd.read_csv(url)
dfht = df[['Height']]

# Plot
pop_ht = np.random.normal(size=50,loc=66.36756, scale=3.84) #a normal dist adj to Mean and Std

fig, ax = plt.subplots();
sns.kdeplot(pop_ht,color="r", shade = True, label="Adults heights");
sns.histplot(df_sample, x = 'Height', stat = 'probability', kde = True, color="dodgerblue", label="Sample Men heights",bins = 6); 

plt.axvline(x=68.929605, color='b', dashes=(3, 3), zorder=0,linewidth=1);
plt.axvline(x=66.367560, color='red', dashes=(3, 3), zorder=0,linewidth=1);
plt.xlim(55,80)
plt.ylim(0,.38)
plt.legend();
------------------

[1;31m---------------------------------------------------------------------------[0m
[1;31mNameError[0m                                 Traceback (most recent call last)
[1;32m~\AppData\Local\Temp\ipykernel_106164\4217146444.py[0m in [0;36m<module>[1;34m[0m
[0;32m     15[0m [0mfig[0m[1;33m,[0m [0max[0m [1;33m=[0m [0mplt[0m[1;33m.[0m[0msubplots[0m[1;33m([0m[1;33m)[0m[1;33m;[0m[1;33m[0m[1;33m[0m[0m
[0;32m     16[0m [0msns[0m[1;33m.[0m[0mkdeplot[0m[1;33m([0m[0mpop_ht[0m[1;33m,[0m[0mcolor[0m[1;33m=[0m[1;34m"r"[0m[1;33m,[0m [0mshade[0m [1;33m=[0m [1;32mTrue[0m[1;33m,[0m [0mlabel[0m[1;33m=[0m[1;34m"Adults heights"[0m[1;33m)[0m[1;33m;[0m[1;33m[0m[1;33m[0m[0m
[1;32m---> 17[1;33m [0msns[0m[1;33m.[0m[0mhistplot[0m[1;33m([0m[0mdf_sample[0m[1;33m,[0m [0mx[0m [1;33m=[0m [1;34m'Height'[0m[1;33m,[0m [0mstat[0m [1;33m=[0m [1;34m'probability'[0m[1;33m,[0m [0mkde[0m [1;33m=[0m [1;32mTrue[0m[1;33m,[0m [0mcolor[0m[1;33m=[0m[1;34m"dodgerblue"[0m[1;33m,[0m [0mlabel[0m[1;33m=[0m[1;34m"Sample Men heights"[0m[1;33m,[0m[0mbins[0m [1;33m=[0m [1;36m6[0m[1;33m)[0m[1;33m;[0m[1;33m[0m[1;33m[0m[0m
[0m[0;32m     18[0m [1;33m[0m[0m
[0;32m     19[0m [0mplt[0m[1;33m.[0m[0maxvline[0m[1;33m([0m[0mx[0m[1;33m=[0m[1;36m68.929605[0m[1;33m,[0m [0mcolor[0m[1;33m=[0m[1;34m'b'[0m[1;33m,[0m [0mdashes[0m[1;33m=[0m[1;33m([0m[1;36m3[0m[1;33m,[0m [1;36m3[0m[1;33m)[0m[1;33m,[0m [0mzorder[0m[1;33m=[0m[1;36m0[0m[1;33m,[0m[0mlinewidth[0m[1;33m=[0m[1;36m1[0m[1;33m)[0m[1;33m;[0m[1;33m[0m[1;33m[0m[0m

[1;31mNameError[0m: name 'df_sample' is not defined
NameError: name 'df_sample' is not defined

